Workbook

Sheet COMPANY_INFO
A1: COMPANY INFO — central inputs for this template
A2: Update the values in column C. All other tabs reference these.
A4: Identity | D4: Notes
A5: Company name | C5: Space Exploration Technologies Corp. (SpaceX) | D5: Used in the IPO_Analysis title
A6: Ticker | C6: SPCX
A7: Exchange | C7: NYSE
A8: Industry / sector | C8: Aerospace / Connectivity / AI
A9: Report date | C9: May 20, 2026 (preliminary S-1)
A11: Fiscal years | D11: Notes
A12: Latest fiscal year | C12: FY 2025 | D12: Drives all year headers on every tab
A13: Prior year | C13: FY 2024
A14: Year +1 (forecast) | C14: FY 2026E
A15: Year +2 (forecast) | C15: FY 2027E
A16: Year +3 (forecast) | C16: FY 2028E
A17: Year +4 (forecast) | C17: FY 2029E
A19: Offering structure | D19: Notes
A20: Underwriter / lead bookrunner | C20: Goldman Sachs / Morgan Stanley (placeholder)
A21: Use of proceeds (one-liner) | C21: GP&E, AI/data center capex, debt repayment, working capital
A22: Lock-up period (days) | C22: 180
A23: Greenshoe % of base | C23: 0.15 | D23: Used by IPO_Analysis to compute greenshoe shares
A24: Underwriter discount % | C24: 0.07 | D24: Net proceeds = gross * (1 - discount)
A26: Color legend
A27: Blue | C27: Hardcoded inputs — change these
A28: Black | C28: Formulas — do not overwrite
A29: Green | C29: Links from another tab
A30: Red | C30: External / disclaimer / negative variance

Sheet TERMS
A1: *THIS SHEET IS FOR EDUCATION AND INFORMATIONAL PURPOSES ONLY -> ASSUME THERE ARE ERRORS -> NOT AN ENDORSEMENT TO BUY OR SELL SECURITIES DO YOUR OWN WORK
A2: *BY OPENING THIS SHEET YOU AGREE THIS IS FOR INFORMATIONAL PURPOSES AND NOTHING IN HERE IS ADVICE
A3: **DRAFT SUBJECT TO CHANGE

Sheet TAM
A1: SpaceX TAM & Market Opportunity — Per S-1 (May 20, 2026)
A2: All values in $B. Source: SpaceX S-1 preliminary filing, May 20, 2026.
A4: SECTION 1: HEADLINE TAM
A5: Company estimates quantifiable TAM at $28.5T (excludes China and Russia).
A7: Segment | B7: TAM ($B) | C7: % of Quantified TAM | D7: Company Framing
A8: Space | B8: 370 | C8: =B8/$B$11 -> 0.013009845 | D8: Launch, manufacturing, PNT, satellite ops, gov agency uncontracted spend
A9: Connectivity | B9: 1610 | C9: =B9/$B$11 -> 0.056610408 | D9: Starlink Broadband + Starlink Mobile
A10: AI | B10: 26460 | C10: =B10/$B$11 -> 0.93037975 | D10: Infrastructure, subscriptions, advertising, enterprise applications
A11: Total quantified TAM (sum) | B11: =SUM(B8:B10) -> 28440 | C11: =B11/$B$11 -> 1 | D11: Rounded company estimate = $28.5T
A12: Company rounded figure | B12: 28500
A13: Rounding gap | B13: =B12-B11 -> 60
A15: SECTION 2: SEGMENT BUILD
A17: Sub-segment | B17: TAM ($B) | C17: Parent segment | D17: Methodology / Source
A18: Space-enabled solutions | B18: 370 | C18: Space | D18: Novaspace 2025 market estimate
A19: Starlink Broadband — Consumer | B19: 660 | C19: Connectivity | D19: 1.8B households × $31/mo × 12 = $670B (rounded to $660B)
A20: Starlink Broadband — Enterprise | B20: 200 | C20: Connectivity | D20: Grand View Research, global biz broadband 2025
A21: Starlink Broadband — Government | B21: 5 | C21: Connectivity | D21: Novaspace, publicly disclosed gov programs only
A22: Starlink Mobile | B22: 740 | C22: Connectivity | D22: 8.0B devices × $8/mo × 12 = $768B (stated $740B)
A23: AI Infrastructure | B23: 2400 | C23: AI | D23: 104M GPUs × 80% utilization × 8,760 hrs × $3.33/GPU-hr = $2.43T
A24: AI Consumer Subscriptions | B24: 760 | C24: AI | D24: 5.5B population age 10+ × $12/mo × 12 = $792B
A25: AI Digital Advertising | B25: 600 | C25: AI | D25: S&P Global Market Intelligence, 2025 global digital ad spend
A26: AI Enterprise Applications | B26: 22700 | C26: AI | D26: DCO 2026 digital economy estimate (broad ceiling)
A27: Total quantified sub-segments | B27: =SUM(B18:B26) -> 28435 | D27: Sum of all quantified sub-segments
A29: SECTION 3: KEY FORMULAS & ASSUMPTIONS
A31: Starlink Consumer Broadband | B31: Input | C31: Value | D31: Notes
B32: Global households (2025) | C32: 1.8 | D32: Billions
B33: Weighted avg monthly ARPU | C33: 31 | D33: $/month
B34: High-income ARPU | C34: 43 | D34: $/month
B35: Upper-middle ARPU | C35: 16 | D35: $/month
B36: Lower-middle / low-income ARPU | C36: 9 | D36: $/month
B37: Calculated TAM ($B) | C37: =C32*C33*12 -> 669.6 | D37: Households × ARPU × 12
B38: Company stated TAM ($B) | C38: 660 | D38: Rounded / region-weighted
A40: Starlink Mobile | B40: Input | C40: Value | D40: Notes
B41: Global mobile devices (Dec 31 2025) | C41: 8 | D41: Billions
B42: Weighted avg monthly ARPU | C42: 8 | D42: $/month
B43: High-income ARPU | C43: 18 | D43: $/month
B44: Upper-middle ARPU | C44: 5 | D44: $/month
B45: Lower-middle / low-income ARPU | C45: 2 | D45: $/month
B46: Calculated TAM ($B) | C46: =C41*C42*12 -> 768 | D46: Devices × ARPU × 12
B47: Company stated TAM ($B) | C47: 740 | D47: Rounded down for region weighting
...

Sheet IPO_Analysis
A1: =COMPANY_INFO!C5 & " — IPO Analysis" -> Space Exploration Technologies Corp. (SpaceX) — IPO Analysis
A2: *THIS SHEET IS FOR EDUCATION AND INFORMATIONAL PURPOSES ONLY -> ASSUME THERE ARE ERRORS -> NOT AN ENDORSEMENT TO BUY OR SELL SECURITIES DO YOUR OWN WORK
A3: SECTION 1: IPO OFFERING DETAILS & VALUATION
A4: ($ in thousands, except per share and share data)
C5: Assumptions | E5: Implied Valuation
A6: Offering Details
A7: Primary shares offered | C7: 800000000
A8: Greenshoe (15% over-allotment) | C8: =C7*0.15 -> 120000000
A9: Total shares offered (incl. greenshoe) | C9: =C7+C8 -> 920000000
A11: Price Range
A12: Low | C12: 110
A13: Midpoint | C13: =(C12+C14)/2 -> 125
A14: High | C14: 140
C15: =+C13*C9/1000000 -> 115000
A16: Gross Proceeds (at midpoint)
A17: Primary offering | E17: =C7*C13 -> 100000000000
A18: Incl. greenshoe | E18: =C9*C13 -> 115000000000
A20: Share Count Summary | C20: Shares
A21: Pre-IPO shares (Class A + B + N) | C21: =Share_Count!C24 -> 12520310769
A22: (+) Primary IPO shares | C22: =C7 -> 800000000
A23: (+) Greenshoe shares | C23: =C8 -> 120000000
A24: Basic shares post-IPO (excl. greenshoe) | C24: =C21+C22 -> 13320310769
A25: Basic shares post-IPO (incl. greenshoe) | C25: =C21+C22+C23 -> 13440310769
A27: (+) Stock options outstanding | C27: =Share_Count!D9 -> 934000000
A28: (+) RSUs outstanding | C28: =Share_Count!D10 -> 129000000
A29: (+) Performance & market condition awards | C29: =Share_Count!D12 -> 0
A30: (+) EchoStar spectrum shares | C30: =Share_Count!D13 -> 261800000
A31: (+) Cursor acquisition option shares | C31: =Share_Count!D14 -> 0
A32: Fully diluted shares post-IPO | C32: =C25+C27+C28+C29+C30+C31 -> 14765110769
A34: Implied Valuation (at midpoint price) | E34: Basic | F34: Fully Diluted
A35: Implied market capitalization | E35: =C25*C13 -> 1680038846125 | F35: =C32*C13 -> 1845638846125
A37: (−) Cash & equivalents | E37: =-Annual_Financials!D34*1000 -> -24747000000
A38: (−) Marketable securities | E38: =-Annual_Financials!D35*1000 -> 0
A39: (−) Digital assets | E39: =-Annual_Financials!D36*1000 -> -1637000000
A40: (−) Net IPO proceeds (cash added by IPO) | E40: =-E17*(1-COMPANY_INFO!C24) -> -93000000000
A41: (+) Total debt (current + LT) | E41: =(Annual_Financials!D50+Annual_Financials!D54)*1000 -> 22896000000
A42: Net cash bridge (EV adjustment) | E42: =E37+E38+E39+E40+E41 -> -96488000000
A43: Implied enterprise value (EV) | E43: =E35+E42 -> 1583550846125 | F43: =F35+E42 -> 1749150846125
A45: Valuation Multiples (at midpoint, FY 2025 basis) | E45: Basic | F45: Fully Diluted
A46: FY 2025 Revenue ($000) | C46: =Annual_Financials!D6 -> 18674000
...

Sheet Share_Count
A1: SpaceX Fully Diluted Share Count Extract — Mar 31, 2026 pro forma
A3: Category | B3: Component | C3: Class | D3: Known Shares | E3: Include in User-Specified Total? | F3: Include in Full Diluted Total? | G3: Status | H3: Source / Notes
A4: Existing / Old Shares | B4: Pro forma Class A common (incl. preferred conversion & Class C reclass) | C4: Class A | D4: 6824581339 | E4: Y | F4: Y | G4: disclosed | H4: SpaceX S-1, §14
A5: Existing / Old Shares | B5: Pro forma Class B common | C5: Class B | D5: 5695729430 | E5: Y | F5: Y | G5: disclosed | H5: SpaceX S-1, §14
A6: Existing / Old Shares | B6: Post-3/31 share issuances (placeholder) | C6: Class A | D6: 0 | E6: Y | F6: Y | G6: blank | H6: Model input
A7: IPO Shares | B7: Common stock offered by company in IPO | C7: Class A | E7: Y | F7: Y | G7: disclosed at pricing | H7: Pricing prospectus — input in IPO_Analysis
A8: IPO Shares | B8: Underwriters' over-allotment option (greenshoe) | C8: Class A | E8: Y | F8: Y | G8: disclosed at pricing | H8: Computed in IPO_Analysis
A9: Equity Awards | B9: Outstanding stock options at Mar 31, 2026 | C9: Class A/B/C | D9: 934000000 | E9: Y | F9: Y | G9: disclosed | H9: SpaceX S-1, §15 reserve table
A10: Equity Awards | B10: Outstanding RSUs at Mar 31, 2026 | C10: Class A/B/C | D10: 129000000 | E10: Y | F10: Y | G10: disclosed | H10: SpaceX S-1, §15 reserve table
A11: Equity Awards | B11: Performance & market condition awards (excl. from diluted EPS) | C11: Class B | D11: 1319100000 | E11: Y | F11: Y | G11: disclosed | H11: SpaceX S-1, §15 + §16
A12: Equity Awards | B12: Founder / additional PRSUs (already in performance awards) | C12: Class B | D12: 0 | E12: Y | F12: Y | G12: included in row 11 | H12: SpaceX S-1, §15
A13: Warrants | B13: EchoStar spectrum equity consideration | C13: Class A | D13: 261800000 | E13: N | F13: Y | G13: disclosed | H13: SpaceX S-1, §13 + §15
A14: Warrants | B14: Cursor acquisition option ($60B / VWAP) | C14: Class A | D14: 0 | E14: N | F14: N | G14: contingent | H14: SpaceX S-1, §16
A15: Warrants | E15: N | F15: N
A16: Warrants | E16: N | F16: N
A17: Future Issuance Reserve | B17: A&R 2024 Plan future grant reserve | C17: Class A/C | D17: 500000000 | E17: Y | F17: Y | G17: disclosed | H17: SpaceX S-1, §15
A18: Future Issuance Reserve | B18: A&R 2017 ESPP reserve | C18: Class A | D18: 75000000 | E18: Y | F18: Y | G18: disclosed | H18: SpaceX S-1, §15
A19: Future Issuance Reserve | B19: Prior plan recycling / forfeitures | C19: Class A | D19: 0 | E19: Y | F19: Y | G19: future recycling
A20: Future Issuance Reserve | D20: 0 | E20: N | F20: N
A23: Summary | B23: Formula / Definition | C23: Known Shares | D23: Notes
A24: Known old shares | B24: Actual common + preferred conversion + post-12/31 Class N issued | C24: =SUM(D4:D6) -> 12520310769 | D24: Excludes unknown RSU net settlement and IPO shares
A25: Known user-specified diluted subtotal | B25: Rows marked Y in Include in User-Specified Total | C25: =SUMIF(E4:E20,"Y",D4:D20) -> 15477410769 | D25: Excludes blanks because preliminary filing omits some counts
A26: Known fully diluted subtotal incl. warrants | B26: Rows marked Y in Include in Full Diluted Total | C26: =SUMIF(F4:F20,"Y",D4:D20) -> 15739210769 | D26: Set F-column to Y for warrants that should be additive to fully diluted; flag exercised warrants N to avoid double-count
A27: Required unknown share-count fields | B27: Count of required included rows with missing Known Shares | C27: =COUNTIFS(G4:G20,"blank",F4:F20,"Y")+COUNTIFS(G4:G20,"future recycling",F4:F20,"Y") -> 2 | D27: These must be populated after final pricing / later filing amendment

Sheet Annual_Financials
A1: Annual Financials — SpaceX (FY 2025 / FY 2024 / FY 2023)
A3: Section | B3: Metric | C3: Units | D3: FY 2025 | E3: FY 2024 | F3: FY 2023 | G3: YoY % (25/24) | H3: Source / Notes
A4: Income Statement | B4: Revenue — Products (hardware) | C4: $000 | D4: 1510000 | E4: 1470000 | F4: 1093000 | G4: =IFERROR(D4/E4-1,"n.m.") -> 0.027210884 | H4: Prospectus Summary / Summary Consolidated Financial Data.
A5: Income Statement | B5: Revenue — Services (Connectivity services, Launch, Ads, AI) | C5: $000 | D5: =D6-D4 -> 17164000 | E5: =E6-E4 -> 12545000 | F5: =F6-F4 -> 9294000 | G5: =IFERROR(D5/E5-1,"n.m.") -> 0.3681945 | H5: Prospectus Summary / Summary Consolidated Financial Data.
A6: Income Statement | B6: Total revenue | C6: $000 | D6: 18674000 | E6: 14015000 | F6: 10387000 | G6: =IFERROR(D6/E6-1,"n.m.") -> 0.33242954 | H6: Prospectus Summary / Summary Consolidated Financial Data.
A7: Income Statement | B7: Cost of revenue — Products | C7: $000 | F7: =D7-E7 -> 0 | G7: n.m. | H7: Prospectus Summary / Summary Consolidated Financial Data.
A8: Income Statement | B8: Cost of revenue — Services | C8: $000 | F8: =D8-E8 -> 0 | G8: n.m. | H8: Prospectus Summary / Summary Consolidated Financial Data.
A9: Income Statement | B9: Total cost of revenue | C9: $000 | D9: 9451000 | E9: 7996000 | F9: 6110000 | G9: =IFERROR(D9/E9-1,"n.m.") -> 0.18196598 | H9: Prospectus Summary / Summary Consolidated Financial Data.
A10: Income Statement | B10: Gross profit | C10: $000 | D10: =D6-D9 -> 9223000 | E10: =E6-E9 -> 6019000 | F10: =F6-F9 -> 4277000 | G10: =IFERROR(D10/E10-1,"n.m.") -> 0.53231434 | H10: Prospectus Summary / Summary Consolidated Financial Data.
A11: Income Statement | B11: Research and development | C11: $000 | D11: 8643000 | E11: 3464000 | F11: 2105000 | G11: =IFERROR(D11/E11-1,"n.m.") -> 1.4950924 | H11: Prospectus Summary / Summary Consolidated Financial Data.
A12: Income Statement | B12: Selling, general & administrative | C12: $000 | D12: 2644000 | E12: 1813000 | F12: 1665000 | G12: =IFERROR(D12/E12-1,"n.m.") -> 0.45835632 | H12: Prospectus Summary / Summary Consolidated Financial Data.
A13: Income Statement | B13: Restructuring charges | C13: $000 | D13: 487000 | E13: 213000 | F13: 237000 | G13: =IFERROR(D13/E13-1,"n.m.") -> 1.286385 | H13: Prospectus Summary / Summary Consolidated Financial Data.
A14: Income Statement | B14: Impairment | C14: $000 | D14: 38000 | E14: 63000 | F14: 3775000 | G14: =IFERROR(D14/E14-1,"n.m.") -> -0.3968254 | H14: Prospectus Summary / Summary Consolidated Financial Data.
A15: Income Statement | B15: Loss from operations | C15: $000 | D15: =D10-D11-D12-D13-D14 -> -2589000 | E15: =E10-E11-E12-E13-E14 -> 466000 | F15: =F10-F11-F12-F13-F14 -> -3505000 | G15: =IFERROR(D15/E15-1,"n.m.") -> -6.555794 | H15: Prospectus Summary / Summary Consolidated Financial Data.
A16: Income Statement | B16: Interest expense | C16: $000 | D16: -1945000 | E16: -1580000 | F16: -1693000 | G16: =IFERROR(D16/E16-1,"n.m.") -> 0.23101266 | H16: Prospectus Summary / Summary Consolidated Financial Data.
A17: Income Statement | B17: Interest income | C17: $000 | D17: 492000 | E17: 371000 | F17: 249000 | G17: =IFERROR(D17/E17-1,"n.m.") -> 0.32614555 | H17: Prospectus Summary / Summary Consolidated Financial Data.
A18: Income Statement | B18: Other income (expense), net | C18: $000 | D18: -177000 | E18: 985000 | F18: -42000 | G18: =IFERROR(D18/E18-1,"n.m.") -> -1.1796954 | H18: Prospectus Summary / Summary Consolidated Financial Data.
A19: Income Statement | B19: Loss before income taxes | C19: $000 | D19: =D15+D16+D17+D18 -> -4219000 | E19: =E15+E16+E17+E18 -> 242000 | F19: =F15+F16+F17+F18 -> -4991000 | G19: =IFERROR(D19/E19-1,"n.m.") -> -18.433884 | H19: Prospectus Summary / Summary Consolidated Financial Data.
A20: Income Statement | B20: Provision for income taxes | C20: $000 | D20: 718000 | E20: -549000 | F20: -363000 | G20: =IFERROR(D20/E20-1,"n.m.") -> -2.3078324 | H20: Prospectus Summary / Summary Consolidated Financial Data.
A21: Income Statement | B21: Net loss | C21: $000 | D21: =D19-D20 -> -4937000 | E21: =E19-E20 -> 791000 | F21: =F19-F20 -> -4628000 | G21: =IFERROR(D21/E21-1,"n.m.") -> -7.2414665 | H21: Prospectus Summary / Summary Consolidated Financial Data.
A22: Income Statement | B22: Net loss attributable to common shareholders | C22: $000 | D22: =D21 -> -4937000 | E22: =E21 -> 791000 | F22: =F21 -> -4628000 | G22: =IFERROR(D22/E22-1,"n.m.") -> -7.2414665 | H22: Prospectus Summary / Summary Consolidated Financial Data.
A23: Per Share | B23: Basic net loss per share | C23: $/share | D23: -1.69 | E23: 0.01 | F23: -1.68 | G23: =IFERROR(D23/E23-1,"n.m.") -> -170 | H23: Prospectus Summary / Summary Consolidated Financial Data.
A24: Per Share | B24: Diluted net loss per share | C24: $/share | D24: -1.69 | E24: 0 | F24: -1.68 | G24: =IFERROR(D24/E24-1,"n.m.") -> n.m. | H24: Prospectus Summary / Summary Consolidated Financial Data.
A25: Per Share | B25: Weighted average shares — Basic (000s) | C25: 000 shares | D25: 2926000 | E25: 2848000 | F25: 2759000 | G25: =IFERROR(D25/E25-1,"n.m.") -> 0.02738764 | H25: Prospectus Summary / Summary Consolidated Financial Data.
A26: Per Share | B26: Weighted average shares — Diluted (000s) | C26: 000 shares | D26: 2926000 | E26: 9956000 | F26: 2759000 | G26: =IFERROR(D26/E26-1,"n.m.") -> -0.70610687 | H26: Prospectus Summary / Summary Consolidated Financial Data.
A27: Non-GAAP | B27: Adjusted EBITDA | C27: $000 | D27: 6584000 | E27: 5350000 | F27: 3821000 | G27: =IFERROR(D27/E27-1,"n.m.") -> 0.23065421 | H27: Prospectus Summary / Summary Consolidated Financial Data. Operating loss excluding stock-based compensation
A28: Non-GAAP | B28: Non-GAAP net loss (memo) | C28: $000 | F28: =D28-E28 -> 0 | G28: n.m. | H28: Prospectus Summary / Summary Consolidated Financial Data. Net income/loss excluding stock-based compensation and FV change/extinguishment of forward contract liability
A29: Stock-Based Compensation | B29: SBC — Cost of revenue | C29: $000 | F29: =D29-E29 -> 0 | G29: n.m. | H29: Prospectus Summary / Summary Consolidated Financial Data.
A30: Stock-Based Compensation | B30: SBC — Research and development | C30: $000 | F30: =D30-E30 -> 0 | G30: n.m. | H30: Prospectus Summary / Summary Consolidated Financial Data.
A31: Stock-Based Compensation | B31: SBC — Selling, general & administrative | C31: $000 | F31: =D31-E31 -> 0 | G31: n.m. | H31: Prospectus Summary / Summary Consolidated Financial Data.
A32: Stock-Based Compensation | B32: SBC — Restructuring/Other | C32: $000 | F32: =D32-E32 -> 0 | G32: n.m. | H32: Prospectus Summary / Summary Consolidated Financial Data.
A33: Stock-Based Compensation | B33: Total stock-based compensation expense | C33: $000 | D33: 1307000 | E33: 981000 | F33: 727000 | G33: =IFERROR(D33/E33-1,"n.m.") -> 0.33231397 | H33: Prospectus Summary / Summary Consolidated Financial Data.
A34: Balance Sheet (period-end) | B34: Cash and cash equivalents | C34: $000 | D34: 24747000 | E34: 11385000 | F34: =D34-E34 -> 13362000 | G34: =IFERROR(D34/E34-1,"n.m.") -> 1.1736495 | H34: Consolidated Balance Sheets.
A35: Balance Sheet | B35: Marketable securities (short-term) | C35: $000 | D35: 0 | E35: 800000 | F35: =D35-E35 -> -800000 | G35: n.m. | H35: Consolidated Balance Sheets.
A36: Balance Sheet | B36: Digital assets | C36: $000 | D36: 1637000 | E36: 1749000 | F36: =D36-E36 -> -112000 | G36: =IFERROR(D36/E36-1,"n.m.") -> -0.064036592 | H36: Consolidated Balance Sheets.
A37: Balance Sheet | B37: Accounts receivable, net | C37: $000 | D37: 1579000 | E37: 1052000 | F37: =D37-E37 -> 527000 | G37: =IFERROR(D37/E37-1,"n.m.") -> 0.50095057 | H37: Consolidated Balance Sheets.
A38: Balance Sheet | B38: Inventory | C38: $000 | D38: 2416000 | E38: 2003000 | F38: =D38-E38 -> 413000 | G38: =IFERROR(D38/E38-1,"n.m.") -> 0.20619071 | H38: Consolidated Balance Sheets.
A39: Balance Sheet | B39: Prepaid and other current assets | C39: $000 | D39: 2210000 | E39: 868000 | F39: =D39-E39 -> 1342000 | G39: =IFERROR(D39/E39-1,"n.m.") -> 1.5460829 | H39: Consolidated Balance Sheets.
A40: Balance Sheet | B40: Total current assets | C40: $000 | D40: 30952000 | E40: 16108000 | F40: =D40-E40 -> 14844000 | G40: =IFERROR(D40/E40-1,"n.m.") -> 0.92152967 | H40: Consolidated Balance Sheets.
A41: Balance Sheet | B41: Property, plant & equipment, net | C41: $000 | D41: 42602000 | E41: 21147000 | F41: =D41-E41 -> 21455000 | G41: =IFERROR(D41/E41-1,"n.m.") -> 1.0145647 | H41: Consolidated Balance Sheets.
...

Sheet KPIs
A1: SpaceX KPI Summary — Annual (FY 2025 / FY 2024 / FY 2023)
A3: Metric | B3: Units | C3: FY 2025 | D3: FY 2024 | E3: FY 2023 | F3: Notes / Formula | G3: Source
A4: Total revenue growth | B4: % | C4: =Annual_Financials!D6/Annual_Financials!E6-1 -> 0.33242954 | D4: =Annual_Financials!E6/Annual_Financials!F6-1 -> 0.34928276 | E4: n.a. | F4: FY25 / FY24 - 1 | G4: SpaceX S-1, §3
A5: Space segment revenue | B5: 0 | C5: 4086000 | D5: 3796000 | E5: 3557000 | F5: Customer launches + Launch & Development | G5: SpaceX S-1, §5
A6: Connectivity segment revenue | B6: 0 | C6: 11387000 | D6: 7599000 | E6: 3869000 | F6: Consumer Starlink + Enterprise/Gov + Mobile | G6: SpaceX S-1, §5
A7: AI segment revenue | B7: 0 | C7: 3201000 | D7: 2620000 | E7: 2961000 | F7: Advertising + AI Solutions & Infrastructure | G7: SpaceX S-1, §5
A8: Gross margin | B8: % | C8: =Annual_Financials!D10/Annual_Financials!D6 -> 0.49389526 | D8: =Annual_Financials!E10/Annual_Financials!E6 -> 0.42946843 | E8: =Annual_Financials!F10/Annual_Financials!F6 -> 0.41176471 | F8: Gross profit / revenue | G8: Annual_Financials
A9: Operating margin | B9: % | C9: =Annual_Financials!D15/Annual_Financials!D6 -> -0.13864196 | D9: =Annual_Financials!E15/Annual_Financials!E6 -> 0.033250089 | E9: =Annual_Financials!F15/Annual_Financials!F6 -> -0.33744103 | F9: Operating income (loss) / revenue | G9: Annual_Financials
A10: Net margin | B10: % | C10: =Annual_Financials!D21/Annual_Financials!D6 -> -0.26437828 | D10: =Annual_Financials!E21/Annual_Financials!E6 -> 0.056439529 | E10: =Annual_Financials!F21/Annual_Financials!F6 -> -0.44555695 | F10: Net income (loss) / revenue | G10: Annual_Financials
A11: Adjusted EBITDA | B11: 0 | C11: 6584000 | D11: 5350000 | E11: 3821000 | F11: Non-GAAP EBITDA | G11: SpaceX S-1, §2-3
A12: Adjusted EBITDA margin | B12: % | C12: =C11/Annual_Financials!D6 -> 0.35257577 | D12: =D11/Annual_Financials!E6 -> 0.38173386 | E12: =E11/Annual_Financials!F6 -> 0.36786368 | F12: Adj EBITDA / revenue | G12: Annual_Financials
A13: R&D as % of revenue | B13: % | C13: =Annual_Financials!D11/Annual_Financials!D6 -> 0.46283603 | D13: =Annual_Financials!E11/Annual_Financials!E6 -> 0.24716375 | E13: =Annual_Financials!F11/Annual_Financials!F6 -> 0.20265717 | F13: R&D / revenue | G13: Annual_Financials
A14: SG&A as % of revenue | B14: % | C14: =Annual_Financials!D12/Annual_Financials!D6 -> 0.14158723 | D14: =Annual_Financials!E12/Annual_Financials!E6 -> 0.1293614 | E14: =Annual_Financials!F12/Annual_Financials!F6 -> 0.16029652 | F14: SG&A / revenue | G14: Annual_Financials
A15: Starlink subscribers (millions) | B15: M | C15: 8.9 | D15: 4.4 | E15: 2.3 | F15: Period-end Starlink subscriber count | G15: SpaceX S-1, §7
A16: Starlink monthly ARPU | B16: $ | C16: 81 | D16: 91 | E16: 99 | F16: Consumer monthly ARPU | G16: SpaceX S-1, §7
A17: Starlink satellites in LEO | B17: # | C17: 9600 | E17: Broadband + mobile satellites in low earth orbit | F17: Broadband + mobile satellites in LEO | G17: SpaceX S-1, §7
A18: Countries / markets served | B18: # | C18: 164 | E18: Countries, territories, and markets | F18: Countries, territories, and markets | G18: SpaceX S-1, §7
A19: Mass to orbit (metric tons) | B19: MT | C19: 2213 | D19: 1699 | E19: 1210 | F19: Total mass delivered to orbit | G19: SpaceX S-1, §6
A20: Total launches | B20: # | C20: 170 | D20: 138 | E20: 98 | F20: Falcon + Starship launches | G20: SpaceX S-1, §6
A21: Customer Falcon launches | B21: # | C21: 43 | D21: 45 | E21: 33 | F21: External customer launches | G21: SpaceX S-1, §6
A22: Internal Falcon launches | B22: # | C22: 122 | D22: 89 | E22: 63 | F22: Starlink internal launches | G22: SpaceX S-1, §6
A23: AI compute capacity (GW) | B23: GW | C23: 0.8 | D23: 0.3 | E23: 0 | F23: Nameplate compute draw | G23: SpaceX S-1, §8
A24: Grok/X monthly active users (M) | B24: M | C24: 520 | D24: 520 | E24: Combined Grok + X MAUs | F24: Combined Grok + X MAUs | G24: SpaceX S-1, §8
A25: AI paid subscribers (M) | B25: M | C25: 6.3 | E25: X Premium + SuperGrok subscribers | F25: X Premium + SuperGrok subscribers | G25: SpaceX S-1, §8
A26: Total capex | B26: 0 | C26: 20737000 | D26: 11163000 | E26: 4415000 | F26: Across Space, Connectivity, AI | G26: SpaceX S-1, §9
A27: Space capex | B27: 0 | C27: 3832000 | D27: 2032000 | E27: 1497000 | F27: Falcon, Starship, launch facilities | G27: SpaceX S-1, §9
A28: Connectivity capex | B28: 0 | C28: 4178000 | D28: 3498000 | E28: 2455000 | F28: Starlink satellites + ground stations | G28: SpaceX S-1, §9
A29: AI capex | B29: 0 | C29: 12727000 | D29: 5633000 | E29: 463000 | F29: GPUs, data centers, power | G29: SpaceX S-1, §9
A30: Operating cash flow | B30: 0 | C30: =Annual_Financials!D60 -> 6785000 | D30: =Annual_Financials!E60 -> 5776000 | E30: =Annual_Financials!F60 -> 4520000 | F30: Net cash from operating activities | G30: Annual_Financials
A31: Free cash flow (OCF - Capex) | B31: 0 | C31: =Annual_Financials!D60+Annual_Financials!D80 -> -13952000 | D31: =Annual_Financials!E60+Annual_Financials!E80 -> -5387000 | E31: =Annual_Financials!F60+Annual_Financials!F80 -> 105000 | F31: OCF minus capex | G31: Derived (OCF - capex)
A32: Cash + Marketable securities | B32: 0 | C32: =Annual_Financials!D34+Annual_Financials!D35 -> 24747000 | D32: =Annual_Financials!E34+Annual_Financials!E35 -> 12185000 | E32: Liquid assets | F32: Liquid assets (cash + mkt sec) | G32: Annual_Financials
A33: Total debt (current + LT) | B33: 0 | C33: =Annual_Financials!D50+Annual_Financials!D54 -> 22896000 | D33: =Annual_Financials!E50+Annual_Financials!E54 -> 13793000 | E33: Including finance leases | F33: Including finance leases | G33: Annual_Financials
A34: Net debt | B34: 0 | C34: =C33-C32 -> -1851000 | D34: =D33-D32 -> 1608000 | E34: Total debt - liquidity | F34: Total debt - liquidity | G34: Derived
A35: Deferred revenue (total) | B35: 0 | C35: =Annual_Financials!D49+Annual_Financials!D53 -> 12116000 | D35: =Annual_Financials!E49+Annual_Financials!E53 -> 10179000 | E35: Current + non-current | F35: Current + non-current deferred revenue | G35: Annual_Financials
A36: Backlog | B36: 0 | C36: 28377000 | D36: 28377000 | E36: Contracted future revenue | F36: Contracted future revenue | G36: SpaceX S-1, §12
A37: Bridge Loan outstanding | B37: 0 | C37: 20000000 | E37: Bridge Loan principal | F37: Bridge Loan principal | G37: SpaceX S-1, §13
C38: =Annual_Financials!D40/Annual_Financials!E40-1 -> 0.92152967
C39: =Annual_Financials!D41/Annual_Financials!E41-1 -> 1.0145647
C40: =Annual_Financials!D42/Annual_Financials!E42-1 -> -0.25266904
C41: =Annual_Financials!D43/Annual_Financials!E43-1 -> -0.29986431
...

Sheet Checks
A1: Validation Checks — SpaceX Model
A3: Check | B3: Formula / Basis | C3: Result | D3: Expected / Interpretation | E3: Status
A4: Revenue tie (FY 2025) | B4: Products + Services revenue = Total revenue (D6) | C4: =Annual_Financials!D4+Annual_Financials!D5-Annual_Financials!D6 -> 0 | D4: 0 | E4: =IF(C4=0,"OK","CHECK") -> OK
A5: Revenue tie (FY 2024) | B5: Products + Services revenue = Total revenue (E6) | C5: =Annual_Financials!E4+Annual_Financials!E5-Annual_Financials!E6 -> 0 | D5: 0 | E5: =IF(C5=0,"OK","CHECK") -> OK
A6: Cost of revenue tie (FY 2025) | B6: Products + Services COGS = Total COGS (D9). NOTE: SpaceX doesn't disclose by line; D7/D8 left blank. | C6: =IF(AND(Annual_Financials!D7="",Annual_Financials!D8=""),0,Annual_Financials!D7+Annual_Financials!D8-Annual_Financials!D9) -> 0 | D6: 0 | E6: =IF(C6=0,"OK","CHECK") -> OK
A7: Cost of revenue tie (FY 2024) | B7: Products + Services COGS = Total COGS (E9). NOTE: SpaceX doesn't disclose by line; E7/E8 left blank. | C7: =IF(AND(Annual_Financials!E7="",Annual_Financials!E8=""),0,Annual_Financials!E7+Annual_Financials!E8-Annual_Financials!E9) -> 0 | D7: 0 | E7: =IF(C7=0,"OK","CHECK") -> OK
A8: Gross profit tie (FY 2025) | B8: Total revenue - Total COGS = Gross profit (D10) | C8: =Annual_Financials!D6-Annual_Financials!D9-Annual_Financials!D10 -> 0 | D8: 0 | E8: =IF(C8=0,"OK","CHECK") -> OK
A9: Gross profit tie (FY 2024) | B9: Total revenue - Total COGS = Gross profit (E10) | C9: =Annual_Financials!E6-Annual_Financials!E9-Annual_Financials!E10 -> 0 | D9: 0 | E9: =IF(C9=0,"OK","CHECK") -> OK
A10: OpEx tie (FY 2025) | B10: R&D + SG&A + Restructuring + Impairment vs sum-of-parts check | C10: =Annual_Financials!D11+Annual_Financials!D12+Annual_Financials!D13+Annual_Financials!D14-(Annual_Financials!D10-Annual_Financials!D15) -> 0 | D10: 0 | E10: =IF(C10=0,"OK","CHECK") -> OK
A11: OpEx tie (FY 2024) | B11: R&D + SG&A + Restructuring + Impairment vs sum-of-parts check | C11: =Annual_Financials!E11+Annual_Financials!E12+Annual_Financials!E13+Annual_Financials!E14-(Annual_Financials!E10-Annual_Financials!E15) -> 0 | D11: 0 | E11: =IF(C11=0,"OK","CHECK") -> OK
A12: Operating income tie (FY 2025) | B12: Gross profit - (R&D + SG&A + Restr + Impair) - Operating loss (D15) = 0 | C12: =Annual_Financials!D10-(Annual_Financials!D11+Annual_Financials!D12+Annual_Financials!D13+Annual_Financials!D14)-Annual_Financials!D15 -> 0 | D12: 0 | E12: =IF(C12=0,"OK","CHECK") -> OK
A13: Operating income tie (FY 2024) | B13: Gross profit - (R&D + SG&A + Restr + Impair) - Operating income/loss (E15) = 0 | C13: =Annual_Financials!E10-(Annual_Financials!E11+Annual_Financials!E12+Annual_Financials!E13+Annual_Financials!E14)-Annual_Financials!E15 -> 0 | D13: 0 | E13: =IF(C13=0,"OK","CHECK") -> OK
A14: Net income tie (FY 2025) | B14: Pretax (D19) - Tax (D20) - Net loss (D21) = 0 | C14: =Annual_Financials!D19-Annual_Financials!D20-Annual_Financials!D21 -> 0 | D14: 0 | E14: =IF(C14=0,"OK","CHECK") -> OK
A15: Net income tie (FY 2024) | B15: Pretax (E19) - Tax (E20) - Net income (E21) = 0 | C15: =Annual_Financials!E19-Annual_Financials!E20-Annual_Financials!E21 -> 0 | D15: 0 | E15: =IF(C15=0,"OK","CHECK") -> OK
A16: Basic shares subtotal exists | B16: Share_Count!C24 (basic post-IPO incl. greenshoe) | C16: =Share_Count!C24 -> 12520310769 | D16: > 0 once cap table is populated | E16: =IF(C16>0,"OK","CHECK") -> OK
A17: Fully diluted subtotal exists | B17: Share_Count!C26 (fully diluted) | C17: =Share_Count!C26 -> 15739210769 | D17: > 0 once cap table is populated | E17: =IF(C17>0,"OK","CHECK") -> OK
A18: Required unknown fields | B18: Count of cap-table rows flagged as required but not yet populated | C18: =Share_Count!C27 -> 2 | D18: 0 once final S-1 is populated | E18: =IF(C18>0,"OK - prelim blanks","CHECK") -> OK - prelim blanks
A19: Balance sheet tie (Dec 31 2025) | B19: Total assets (D47) = Total liab + Pref + Equity (D59) | C19: =Annual_Financials!D47-Annual_Financials!D59 -> 0 | D19: 0 | E19: =IF(ABS(C19)<1,"OK","CHECK") -> OK
A20: Balance sheet tie (Dec 31 2024) | B20: Total assets (E47) = Total liab + Pref + Equity (E59) | C20: =Annual_Financials!E47-Annual_Financials!E59 -> 0 | D20: 0 | E20: =IF(ABS(C20)<1,"OK","CHECK") -> OK
A21: FY 2025 revenue ties to disclosed | B21: Annual_Financials!D6 = $18,674M ($000) | C21: =Annual_Financials!D6-18674000 -> 0 | D21: 0 | E21: =IF(C21=0,"OK","CHECK") -> OK
A22: FY 2025 net loss ties to disclosed | B22: Annual_Financials!D21 = -$4,937M | C22: =Annual_Financials!D21-(-4937000) -> 0 | D22: 0 | E22: =IF(C22=0,"OK","CHECK") -> OK
A23: FY 2025 Adj EBITDA ties to disclosed | B23: Annual_Financials!D27 = $6,584M | C23: =Annual_Financials!D27-6584000 -> 0 | D23: 0 | E23: =IF(C23=0,"OK","CHECK") -> OK
A24: Pro forma share count ties to disclosed | B24: Share_Count!C24 = 12,520,310,769 | C24: =Share_Count!C24-12520310769 -> 0 | D24: 0 | E24: =IF(C24=0,"OK","CHECK") -> OK
A25: FD shares tie to aggressive walk | B25: Share_Count!C26 = 15,739,210,769 (per markdown §16) | C25: =Share_Count!C26-15739210769 -> 0 | D25: 0 | E25: =IF(C25=0,"OK","CHECK") -> OK
A26: IPO_Analysis FD shares (post-IPO + greenshoe + awards) | B26: IPO_Analysis!C32 should be ~14.02B (pro forma + IPO + options + RSUs + perf + EchoStar) | C26: =IPO_Analysis!C32 -> 14765110769 | D26: ~14,017,610,769 | E26: =IF(IPO_Analysis!C32>13000000000,"OK","CHECK") -> OK
A27: IPO midpoint price within range | B27: C13 should be midpoint of C12 (low) and C14 (high) | C27: =IPO_Analysis!C13-(IPO_Analysis!C12+IPO_Analysis!C14)/2 -> 0 | D27: 0 | E27: =IF(ABS(C27)<0.01,"OK","CHECK") -> OK
A28: FD market cap in target range $1.75T - $1.90T | B28: IPO_Analysis!F35 at midpoint | C28: =IPO_Analysis!F35/1000000000 -> 1845.6388 | D28: $1.75T - $1.90T (post-$100B raise) | E28: =IF(AND(IPO_Analysis!F35>1750000000000,IPO_Analysis!F35<1900000000000),"OK","CHECK") -> OK
A29: FY 2025 op margin negative (loss year) | B29: KPIs!C9 should be < 0 | C29: =KPIs!C9 -> -0.13864196 | D29: < 0 | E29: =IF(KPIs!C9<0,"OK","CHECK") -> OK
A30: FY 2025 revenue growth >25% | B30: KPIs!C4 should be ~33% | C30: =KPIs!C4 -> 0.33242954 | D30: ~33% | E30: =IF(KPIs!C4>0.25,"OK","CHECK") -> OK
A31: Segment Adj EBITDA sums to consolidated (FY 2025) | B31: IPO_Analysis!D88 (sum of segments) = Annual_Financials!D27 (consolidated) | C31: =IPO_Analysis!D88-Annual_Financials!D27 -> 0 | D31: 0 | E31: =IF(C31=0,"OK","CHECK") -> OK
A32: Segment Adj EBITDA sums to consolidated (FY 2024) | B32: IPO_Analysis!C88 (sum of segments) = Annual_Financials!E27 (consolidated) | C32: =IPO_Analysis!C88-Annual_Financials!E27 -> 0 | D32: 0 | E32: =IF(C32=0,"OK","CHECK") -> OK
